
В RxJS есть несколько операторов для обработки ошибок и реализации логики повтора. Рассмотрим основные из них:

### Операторы для обработки ошибок

1. **`catchError`**: Позволяет перехватывать ошибки и возвращать новый Observable или бросать ошибку дальше.

```TS
import { of, throwError } from 'rxjs';
import { catchError } from 'rxjs/operators';

of(1, 2, 3)
  .pipe(
    catchError(err => {
      console.error('Ошибка:', err);
      return of('Произошла ошибка'); // Возвращаем новый Observable
    })
  )
  .subscribe(value => console.log(value));
```

2. **`retry`**: Повторяет исходный Observable заданное количество раз в случае ошибки.

```TS
import { of, throwError } from 'rxjs';
import { retry, catchError } from 'rxjs/operators';

throwError('Ошибка!')
  .pipe(
    retry(3), // Повторить 3 раза
    catchError(err => of(`Ловим ошибку после 3 попыток: ${err}`))
  )
  .subscribe(value => console.log(value));
```

3. **`retryWhen`**: Позволяет настроить логику повтора с учетом дополнительных условий, например, задержки между попытками.

```TS
import { of, throwError, timer } from 'rxjs';
import { retryWhen, catchError, delayWhen } from 'rxjs/operators';

throwError('Ошибка!')
  .pipe(
    retryWhen(errors => 
      errors.pipe(
        delayWhen(() => timer(2000)) // Задержка между попытками
      )
    ),
    catchError(err => of(`Ловим ошибку после повторных попыток: ${err}`))
  )
  .subscribe(value => console.log(value));
```

### Пример использования в HTTP-запросах

Допустим, у вас есть HTTP-запрос, который вы хотите повторить в случае ошибки, и обработать ошибку, если все попытки не удались.

```TS
import { HttpClient } from '@angular/common/http';
import { Injectable } from '@angular/core';
import { Observable, throwError } from 'rxjs';
import { catchError, retryWhen, delayWhen } from 'rxjs/operators';
import { timer } from 'rxjs';

@Injectable({
  providedIn: 'root'
})
export class DataService {
  constructor(private http: HttpClient) {}

  getData(): Observable<any> {
    return this.http.get('https://api.example.com/data')
      .pipe(
        retryWhen(errors => 
          errors.pipe(
            delayWhen(() => timer(2000)), // Задержка между попытками
            catchError(err => {
              console.error('Не удалось получить данные:', err);
              return throwError('Ошибка после повторных попыток');
            })
          )
        ),
        catchError(err => {
          console.error('Финальная ошибка:', err);
          return throwError('Произошла ошибка при получении данных');
        })
      );
  }
}
```

### Обработка ошибок в компоненте

```TS
import { Component, OnInit } from '@angular/core';
import { DataService } from './data.service';

@Component({
  selector: 'app-data',
  template: `
    <div *ngIf="error">{{ error }}</div>
    <div *ngIf="data">{{ data | json }}</div>
  `
})
export class DataComponent implements OnInit {
  data: any;
  error: string;

  constructor(private dataService: DataService) {}

  ngOnInit() {
    this.dataService.getData()
      .subscribe(
        data => this.data = data,
        error => this.error = error
      );
  }
}
```

### Заключение

Использование операторов RxJS, таких как `catchError`, `retry`, и `retryWhen`, позволяет гибко обрабатывать ошибки и реализовывать логику повтора. Эти инструменты помогут вам создавать более надежные и устойчивые к ошибкам приложения.